Workbook

Sheet Le Intro
B2: Some Rocket Maker Weird Thing (SomRMWT) - Alpha v0.4.rev1 - 23/09/2026
B4: "Yes, this is real. Yes, I'm bored. No, I do have a life." – Muhammad Naufal Afif, 11/01/2025
B5: What Even Is This? SomRMWT is a rocket designer built using Excel and coded partially in Python, designed for hobby rocketry, academic purposes as teaching tool, or conceptual rocket designs. Started when Muhammad Naufal Afif was bored on his sixth year studying aerospace engineering, it provides "good enough" data as baseline for future rocket designs. Currently, it consists of a data input sheet, a rocket initial sizing tool, and weight analysis tool. Contributions from those with expertise or interest in rocketry are highly encouraged to enhance its capabilities.
B6: Main references: [UwU] Rocket Propulsion Elements, Seventh Edition - George P. Sutton and Oscar Billarz [OwO] Design of Rockets and Space Launch Vehicles, Second Edition - Don Edberg and Willie Costa
B7: Wanna be a co-author? Contact me! -> m.naufal.afif.2001@gmail.com
B8: General Guidelines: Follow the stated instruction for each spreadsheet.
B10: Features to be Added Must Haves Before Entering Beta Stage (Essential Components): 1. Data Input (DONE!) 2. Initial Sizing (DONE!) 3. Rocket Geometry Drawer (a la Taufiq Mulyanto's AISAT) 4. Weight Analysis 5. Engine Performance (complete with thrust chart maker) a. Solid Propellant b. Liquid Propellant 6. Mission Planner Using RocketPy 7. de Laval Nozzle Maker
B11: Must Haves Before Entering Full Release (Optional Components): 1. Benchmarking Against Competitors 2. Payload Maker 3. Engine Performance (complete with thrust chart maker) a. Hybrid Propellant 4. Trajectory Visualiser (integrated to Mission Planner) 5. Cost Analysis 6. Further breakdown as standalone Python/Rust program 7. Aerodynamic Analysis
B12: CO-AUTHORS! PLEASE FILL IN LOG AFTER EDITING! UNLESS MAKING A NEW VERSION, UNLISTED CHANGES ARE NOT RECOGNISED AND WILL BE RECTIFIED!!!

Sheet Data Input
B2: HOW TO TABLE
B4: Easy enough. Just insert your data in the yellow-tinted cells, also the orange one if you're feeling frisky since those are optional. You can add more missions if you like. All other sheets refer to data inputed here
B6: Rocket Name | C6: ROwOcket
B7: Expected Stages | C7: 3
B8: Expected Rocket Size (NASA) | C8: Imouto (2000 - 20000 kg)
B9: Expected Rocket Diameter | C9: 6
B10: Desired Rocket Payload Ratio (0 -1) | C10: 0.01
B13: Attribute | C13: Primary Mission | D13: Secondary Mission | E13: Tertiary Mission | F13: Mission #4 | G13: Mission #5 | H13: Mission #6 | I13: Mission #7 | J13: Mission #8 | K13: Mission #9 | L13: Mission #10
B14: Payload | C14: 15000 | D14: 6000 | E14: 10000
B15: What kind of mission? | C15: LEO (ISS mission mostly) | D15: GEO/GTO | E15: MEO
B16: What kind of orbit? | C16: Circular | D16: Circular | E16: Eliptical
B17: Expected (periapsis) radius | C17: 6771000 | D17: 42164000 | E17: =0.667*DataInputTable[[#This Row],[Secondary Mission]] -> 28123388
B18: Expected semi-major axis | C18: 5000000 | D18: =0.667*D17 -> 28123388 | E18: =0.667*E17 -> 18758300
B19: Assumed ideal single-stage delta-v requirement | C19: =IF( ISBLANK(C16), "Oh nyo, pwease insert orbit type ÓwÒ", IF( C16 = "Circular", INDEX( TheDropdownMenuTable_DataInput[Single-stage delta-v for mission], MATCH( C15, TheDropdownMenuTable_DataInput[What kind of mission? ], 0 ) ), INDEX( DeltaVCalculator_InitialSizing[], MATCH( C15, DeltaVCalculator_InitialSizing[V: Orbit? | -> Orbit type?], 0 ), MATCH( C16, DeltaVCalculator_InitialSizing[#Headers], 0 ) ) ) ) -> 7668.5932 | D19: =IF( ISBLANK(D16), "Oh nyo, pwease insert orbit type ÓwÒ", IF( D16 = "Circular", INDEX( TheDropdownMenuTable_DataInput[Single-stage delta-v for mission], MATCH( D15, TheDropdownMenuTable_DataInput[What kind of mission? ], 0 ) ), INDEX( DeltaVCalculator_InitialSizing[], MATCH( D15, DeltaVCalculator_InitialSizing[V: Orbit? | -> Orbit type?], 0 ), MATCH( D16, DeltaVCalculator_InitialSizing[#Headers], 0 ) ) ) ) -> 10741.654 | E19: =IF( ISBLANK(E16), "Oh nyo, pwease insert orbit type ÓwÒ", IF( E16 = "Circular", INDEX( TheDropdownMenuTable_DataInput[Single-stage delta-v for mission], MATCH( E15, TheDropdownMenuTable_DataInput[What kind of mission? ], 0 ) ), INDEX( DeltaVCalculator_InitialSizing[], MATCH( E15, DeltaVCalculator_InitialSizing[V: Orbit? | -> Orbit type?], 0 ), MATCH( E16, DeltaVCalculator_InitialSizing[#Headers], 0 ) ) ) ) -> 10334.197 | F19: =IF( ISBLANK(F16), "Oh nyo, pwease insert orbit type ÓwÒ", IF( F16 = "Circular", INDEX( TheDropdownMenuTable_DataInput[Single-stage delta-v for mission], MATCH( F15, TheDropdownMenuTable_DataInput[What kind of mission? ], 0 ) ), INDEX( DeltaVCalculator_InitialSizing[], MATCH( F15, DeltaVCalculator_InitialSizing[V: Orbit? | -> Orbit type?], 0 ), MATCH( F16, DeltaVCalculator_InitialSizing[#Headers], 0 ) ) ) ) -> Oh nyo, pwease insert orbit type ÓwÒ | G19: =IF( ISBLANK(G16), "Oh nyo, pwease insert orbit type ÓwÒ", IF( G16 = "Circular", INDEX( TheDropdownMenuTable_DataInput[Single-stage delta-v for mission], MATCH( G15, TheDropdownMenuTable_DataInput[What kind of mission? ], 0 ) ), INDEX( DeltaVCalculator_InitialSizing[], MATCH( G15, DeltaVCalculator_InitialSizing[V: Orbit? | -> Orbit type?], 0 ), MATCH( G16, DeltaVCalculator_InitialSizing[#Headers], 0 ) ) ) ) -> Oh nyo, pwease insert orbit type ÓwÒ | H19: =IF( ISBLANK(H16), "Oh nyo, pwease insert orbit type ÓwÒ", IF( H16 = "Circular", INDEX( TheDropdownMenuTable_DataInput[Single-stage delta-v for mission], MATCH( H15, TheDropdownMenuTable_DataInput[What kind of mission? ], 0 ) ), INDEX( DeltaVCalculator_InitialSizing[], MATCH( H15, DeltaVCalculator_InitialSizing[V: Orbit? | -> Orbit type?], 0 ), MATCH( H16, DeltaVCalculator_InitialSizing[#Headers], 0 ) ) ) ) -> Oh nyo, pwease insert orbit type ÓwÒ | I19: =IF( ISBLANK(I16), "Oh nyo, pwease insert orbit type ÓwÒ", IF( I16 = "Circular", INDEX( TheDropdownMenuTable_DataInput[Single-stage delta-v for mission], MATCH( I15, TheDropdownMenuTable_DataInput[What kind of mission? ], 0 ) ), INDEX( DeltaVCalculator_InitialSizing[], MATCH( I15, DeltaVCalculator_InitialSizing[V: Orbit? | -> Orbit type?], 0 ), MATCH( I16, DeltaVCalculator_InitialSizing[#Headers], 0 ) ) ) ) -> Oh nyo, pwease insert orbit type ÓwÒ | J19: =IF( ISBLANK(J16), "Oh nyo, pwease insert orbit type ÓwÒ", IF( J16 = "Circular", INDEX( TheDropdownMenuTable_DataInput[Single-stage delta-v for mission], MATCH( J15, TheDropdownMenuTable_DataInput[What kind of mission? ], 0 ) ), INDEX( DeltaVCalculator_InitialSizing[], MATCH( J15, DeltaVCalculator_InitialSizing[V: Orbit? | -> Orbit type?], 0 ), MATCH( J16, DeltaVCalculator_InitialSizing[#Headers], 0 ) ) ) ) -> Oh nyo, pwease insert orbit type ÓwÒ | ... L19: =IF( ISBLANK(L16), "Oh nyo, pwease insert orbit type ÓwÒ", IF( L16 = "Circular", INDEX( TheDropdownMenuTable_DataInput[Single-stage delta-v for mission], MATCH( L15, TheDropdownMenuTable_DataInput[What kind of mission? ], 0 ) ), INDEX( DeltaVCalculator_InitialSizing[], MATCH( L15, DeltaVCalculator_InitialSizing[V: Orbit? | -> Orbit type?], 0 ), MATCH( L16, DeltaVCalculator_InitialSizing[#Headers], 0 ) ) ) ) -> Oh nyo, pwease insert orbit type ÓwÒ
B20: Expected gimbal angle | C20: 4 | D20: 4 | E20: 4
B21: Expected mission orbit inclination | C21: 0 | D21: 60 | E21: 0
B22: Expected primary launch site latitude | C22: 7.646643 | D22: 7.646643 | E22: 7.646643
B23: Expected secondary launch site latitude | C23: 28.562106 | D23: 28.562106 | E23: 28.562106
B24: Total delta-v needed | C24: =IFERROR( C19 + SUM( (1.3 * 0.5 * 3.14159265358979 * (0.5 * $C$9)^2) / (9.81 * C14 * (2 - $C$10)), (9.81 * (1 - GEOMEAN($C$20:$L$20))), (2 * C19 * SIN(RADIANS(ABS(C21 - GEOMEAN(C22:C23))) / 2)) ), "Well, that can't happen. Whoops...." ) -> 9611.6724 | D24: =IFERROR( D19 + SUM( (1.3 * 0.5 * 3.14159265358979 * (0.5 * $C$9)^2) / (9.81 * D14 * (2 - $C$10)), (9.81 * (1 - GEOMEAN($C$20:$L$20))), (2 * D19 * SIN(RADIANS(ABS(D21 - GEOMEAN(D22:D23))) / 2)) ), "Well, that can't happen. Whoops...." ) -> 18971.88 | E24: =IFERROR( E19 + SUM( (1.3 * 0.5 * 3.14159265358979 * (0.5 * $C$9)^2) / (9.81 * E14 * (2 - $C$10)), (9.81 * (1 - GEOMEAN($C$20:$L$20))), (2 * E19 * SIN(RADIANS(ABS(E21 - GEOMEAN(E22:E23))) / 2)) ), "Well, that can't happen. Whoops...." ) -> 12962.92 | F24: =IFERROR( F19 + SUM( (1.3 * 0.5 * 3.14159265358979 * (0.5 * $C$9)^2) / (9.81 * F14 * (2 - $C$10)), (9.81 * (1 - GEOMEAN($C$20:$L$20))), (2 * F19 * SIN(RADIANS(ABS(F21 - GEOMEAN(F22:F23))) / 2)) ), "Well, that can't happen. Whoops...." ) -> Well, that can't happen. Whoops.... | G24: =IFERROR( G19 + SUM( (1.3 * 0.5 * 3.14159265358979 * (0.5 * $C$9)^2) / (9.81 * G14 * (2 - $C$10)), (9.81 * (1 - GEOMEAN($C$20:$L$20))), (2 * G19 * SIN(RADIANS(ABS(G21 - GEOMEAN(G22:G23))) / 2)) ), "Well, that can't happen. Whoops...." ) -> Well, that can't happen. Whoops.... | H24: =IFERROR( H19 + SUM( (1.3 * 0.5 * 3.14159265358979 * (0.5 * $C$9)^2) / (9.81 * H14 * (2 - $C$10)), (9.81 * (1 - GEOMEAN($C$20:$L$20))), (2 * H19 * SIN(RADIANS(ABS(H21 - GEOMEAN(H22:H23))) / 2)) ), "Well, that can't happen. Whoops...." ) -> Well, that can't happen. Whoops.... | I24: =IFERROR( I19 + SUM( (1.3 * 0.5 * 3.14159265358979 * (0.5 * $C$9)^2) / (9.81 * I14 * (2 - $C$10)), (9.81 * (1 - GEOMEAN($C$20:$L$20))), (2 * I19 * SIN(RADIANS(ABS(I21 - GEOMEAN(I22:I23))) / 2)) ), "Well, that can't happen. Whoops...." ) -> Well, that can't happen. Whoops.... | J24: =IFERROR( J19 + SUM( (1.3 * 0.5 * 3.14159265358979 * (0.5 * $C$9)^2) / (9.81 * J14 * (2 - $C$10)), (9.81 * (1 - GEOMEAN($C$20:$L$20))), (2 * J19 * SIN(RADIANS(ABS(J21 - GEOMEAN(J22:J23))) / 2)) ), "Well, that can't happen. Whoops...." ) -> Well, that can't happen. Whoops.... | ... L24: =IFERROR( L19 + SUM( (1.3 * 0.5 * 3.14159265358979 * (0.5 * $C$9)^2) / (9.81 * L14 * (2 - $C$10)), (9.81 * (1 - GEOMEAN($C$20:$L$20))), (2 * L19 * SIN(RADIANS(ABS(L21 - GEOMEAN(L22:L23))) / 2)) ), "Well, that can't happen. Whoops...." ) -> Well, that can't happen. Whoops....
H26: {=_xlfn._xlws.PY(0,1,DataInputTable[[Primary Mission]:[Mission '#10]],DataInputTable[Attribute],DataInputTable[[#Headers],[Primary Mission]:[Mission '#10]])} -> #VALUE!
E27: Expected Rocket Statistics | H27: ^ DO NOT EVER TOUCH THIS CELL!!!
E28: Average payload size | F28: {=_xlfn._xlws.PY(1,0)} -> 9654.8938 | G28: kg
E29: Average single-stage ideal delta-v | F29: {=_xlfn._xlws.PY(2,0)} -> 9477.3706 | G29: m.s^-1
E30: Average orbit inclination | F30: {=_xlfn._xlws.PY(3,0)} -> 20 | G30: degrees
E31: Average launch site inclination | F31: {=_xlfn._xlws.PY(4,0)} -> 14.778506 | G31: degrees
E32: Average total delta-v requirement | F32: {=_xlfn._xlws.PY(5,0)} -> 13321.017 | G32: m.s^-1
E33: Maximum total delta-v requirement | F33: {=_xlfn._xlws.PY(6,0)} -> 18971.88 | G33: m.s^-1
B43: DO NOT EDIT THIS TABLE!!!
B44: Expected Rocket Size (NASA) | C44: What kind of mission? | D44: Single-stage delta-v for mission | E44: What kind of orbit?
B45: Smoli (0 - 2000 kg) | C45: LEO (ISS mission mostly) | D45: =IFERROR(((9.81*6371000^2)/(INDEX($C$17:$L$17, (MATCH("LEO (ISS mission mostly)", $C$15:$L$15, 0)))))^0.5, ((9.81*6371000^2)/(6378000+400000))^0.5) -> 7668.5932 | E45: Circular
B46: Imouto (2000 - 20000 kg) | C46: MEO | D46: =IFERROR($D$45+((9.81*6371000^2)/(INDEX($C$17:$L$17,(MATCH("MEO",$C$15:$L$15,0)))))^0.5, $D$45+((9.81*6371000^2)/(6378000+AVERAGE(1000000, 35786000)))^0.5) -> 11431.369 | E46: Eliptical
B47: Beeg (20000 - 50000 lkg) | C47: GEO/GTO | D47: =IFERROR($D$45+((9.81*6371000^2)/(INDEX($C$17:$L$17,(MATCH("GEO/GTO",$C$15:$L$15,0)))))^0.5, $D$45+((9.81*6371000^2)/42164000)^0.5) -> 10741.654 | E47: Parabolic
B48: CHONKER (> 50000 kg) | C48: Translunar (assuming LEO parking orbit) | D48: =$D$45+3200+900 -> 11768.593 | E48: Hyperbolic (assuming a 1 km/s speed)
C49: Trans-Mars (assuming LEO parking orbit) | D49: =$D$45+4300+900 -> 12868.593 | E49: Not applicable
C50: Interplanetary (to Sun) | D50: =$D$45 + GEOMEAN(5500, 3500) + 900 -> 12956.075
C51: Interplanetary (away from Sun) | D51: =$D$45 + GEOMEAN(6300, 7300, 8000, 8200, 8200) + 900 -> 16131.282
B53: NOR THIS ONE!!!
B54: V: Orbit? | -> Orbit type? | C54: Circular | D54: Eliptical | E54: Parabolic | F54: Hyperbolic (assuming a 1 km/s speed)
B55: LEO (ISS mission mostly) | C55: =D45 -> 7668.5932 | D55: =IFERROR( ((9.81 * (6378000 ^ 2)) * ( (2 / INDEX($C$17:$L$17, MATCH("LEO (ISS mission mostly)", $C$15:$L$15, 0))) - (1 / INDEX($C$18:$L$18, MATCH("LEO (ISS mission mostly)", $C$15:$L$15, 0))) ) ) ^ 0.5, ((9.81 * (6378000 ^ 2)) * ( (2 / (6378000 + 400000)) - (1 / (0.667 * (6378000 + 400000))) ) ) ^ 0.5 ) -> 6169.3816 | E55: =IFERROR( ((2 * 9.81 * (6371000 ^ 2)) / INDEX($C$17:$L$17, MATCH("LEO (ISS mission mostly)", $C$15:$L$15, 0))) ^ 0.5, ((2 * 9.81 * (6371000 ^ 2)) / (6371000 + 400000)) ^ 0.5 ) -> 10845.029 | F55: =IFERROR( ((2 * 9.81 * (6371000 ^ 2)) / INDEX($C$17:$L$17, MATCH("LEO (ISS mission mostly)", $C$15:$L$15, 0)) + 1000^2) ^ 0.5, (((2 * 9.81 * (6371000 ^ 2)) / (6371000 + 400000)) + 1000^2) ^ 0.5 ) -> 10891.035
B56: MEO | C56: =D46 -> 11431.369 | D56: =IFERROR($D$45 + ((9.81 * (6378000 ^ 2)) * ( (2 / INDEX($C$17:$L$17, MATCH("MEO", $C$15:$L$15, 0))) - (1 / INDEX($C$18:$L$18, MATCH("MEO", $C$15:$L$15, 0))) ) ) ^ 0.5, $D$45 + ((9.81 * (6378000 ^ 2)) * ( (2 / (6378000 + AVERAGE(1000000, 35786000))) - (1 / (0.667 * (6378000 + AVERAGE(1000000, 35786000)))) ) ) ^ 0.5 ) -> 10334.197 | E56: =IFERROR( ((2 * 9.81 * (6371000 ^ 2)) / INDEX($C$17:$L$17, MATCH("MEO", $C$15:$L$15, 0))) ^ 0.5, ((2 * 9.81 * (6371000 ^ 2)) / (6371000 + AVERAGE(1000000,35786000))) ^ 0.5 ) -> 5321.3679 | F56: =IFERROR( ((2 * 9.81 * (6371000 ^ 2)) / INDEX($C$17:$L$17, MATCH("MEO", $C$15:$L$15, 0)) + 1000^2) ^ 0.5, (((2 * 9.81 * (6371000 ^ 2)) / (6371000 + AVERAGE(1000000,35786000))) + 1000^2) ^ 0.5 ) -> 5414.5135
...

Sheet Initial Sizing
A1: HOW TO TABLE
A3: Insert numbers in yellow-tinted cells. Boosters not supported yet, nor coasting
B5: Desired propellant mass fraction (0 - 1) | C5: 0.9
B6: Desired dry mass ratio (0 - 1) | C6: 0.1
A9: Stage | B9: Final mass | C9: In vacuum? | D9: Fuel type? | E9: Fuel | F9: Specific impulse | G9: Stage dry mass | H9: Propellant mass | I9: Wet mass | J9: Stage delta-v | K9: Burn time | L9: Thrust | M9: Total impulse | N9: Total delta-v | P9: {=_xlfn._xlws.PY(7,1)} -> #VALUE!
A10: Payload | B10: ='Data Input'!$F$28 -> 9654.8938 | G10: =B10 -> 9654.8938
A11: 1 | B11: =G10 -> 9654.8938 | C11: NO | D11: Solid | E11: HTPB (LAPAN) | F11: =IF(LeInitialSizingTable[[#This Row],[Fuel type?]] = "Solid", INDEX(IF(LeInitialSizingTable[[#This Row],[In vacuum?]] = "YES", TheDropdownMenuTable_InitialSizing[Isp (solid, vacuum)], TheDropdownMenuTable_InitialSizing[Isp (solid, SL)]), MATCH(LeInitialSizingTable[[#This Row],[Fuel]], TheDropdownMenuTable_InitialSizing[Fuel (solid)], 0)), IF(LeInitialSizingTable[[#This Row],[Fuel type?]] = "Liquid", INDEX(IF(LeInitialSizingTable[[#This Row],[In vacuum?]] = "YES", TheDropdownMenuTable_InitialSizing[Isp (liquid, vacuum)], TheDropdownMenuTable_InitialSizing[Isp (liquid, SL)]), MATCH(LeInitialSizingTable[[#This Row],[Fuel]], TheDropdownMenuTable_InitialSizing[Fuel (liquid)], 0)), INDEX(IF(LeInitialSizingTable[[#This Row],[In vacuum?]] = "YES", TheDropdownMenuTable_InitialSizing[Isp (IDFK, vacuum)], TheDropdownMenuTable_InitialSizing[Isp (IDFK, SL)]), MATCH(LeInitialSizingTable[[#This Row],[Fuel]], TheDropdownMenuTable_InitialSizing[Fuel (IDFK)], 0)))) -> 220.6 | G11: =$C$6*LeInitialSizingTable[[#This Row],[Final mass]] -> 965.48938 | H11: =($C$5*(LeInitialSizingTable[[#This Row],[Stage dry mass]]+LeInitialSizingTable[[#This Row],[Final mass]]))/(1-$C$5) -> 95583.449 | I11: =LeInitialSizingTable[[#This Row],[Propellant mass]] + LeInitialSizingTable[[#This Row],[Stage dry mass]] -> 96548.938 | J11: =9.81*LeInitialSizingTable[[#This Row],[Specific impulse]]*LN(LeInitialSizingTable[[#This Row],[Wet mass]]/(LeInitialSizingTable[[#This Row],[Stage dry mass]]+LeInitialSizingTable[[#This Row],[Final mass]])) -> 4776.7327 | K11: 30 | L11: =9.81*LeInitialSizingTable[[#This Row],[Specific impulse]]*(LeInitialSizingTable[[#This Row],[Propellant mass]]/LeInitialSizingTable[[#This Row],[Burn time]]) -> 6895026.8 | M11: =LeInitialSizingTable[[#This Row],[Thrust]]*LeInitialSizingTable[[#This Row],[Burn time]] -> 2.068508e+08 | N11: =SUM(J11) -> 4776.7327
A12: 2 | B12: =I11 -> 96548.938 | C12: NO | D12: Solid | E12: HTPB (LAPAN) | F12: =IF(LeInitialSizingTable[[#This Row],[Fuel type?]] = "Solid", INDEX(IF(LeInitialSizingTable[[#This Row],[In vacuum?]] = "YES", TheDropdownMenuTable_InitialSizing[Isp (solid, vacuum)], TheDropdownMenuTable_InitialSizing[Isp (solid, SL)]), MATCH(LeInitialSizingTable[[#This Row],[Fuel]], TheDropdownMenuTable_InitialSizing[Fuel (solid)], 0)), IF(LeInitialSizingTable[[#This Row],[Fuel type?]] = "Liquid", INDEX(IF(LeInitialSizingTable[[#This Row],[In vacuum?]] = "YES", TheDropdownMenuTable_InitialSizing[Isp (liquid, vacuum)], TheDropdownMenuTable_InitialSizing[Isp (liquid, SL)]), MATCH(LeInitialSizingTable[[#This Row],[Fuel]], TheDropdownMenuTable_InitialSizing[Fuel (liquid)], 0)), INDEX(IF(LeInitialSizingTable[[#This Row],[In vacuum?]] = "YES", TheDropdownMenuTable_InitialSizing[Isp (IDFK, vacuum)], TheDropdownMenuTable_InitialSizing[Isp (IDFK, SL)]), MATCH(LeInitialSizingTable[[#This Row],[Fuel]], TheDropdownMenuTable_InitialSizing[Fuel (IDFK)], 0)))) -> 220.6 | G12: =$C$6*LeInitialSizingTable[[#This Row],[Final mass]] -> 9654.8938 | H12: =($C$5*(LeInitialSizingTable[[#This Row],[Stage dry mass]]+LeInitialSizingTable[[#This Row],[Final mass]]))/(1-$C$5) -> 955834.49 | I12: =LeInitialSizingTable[[#This Row],[Propellant mass]] + LeInitialSizingTable[[#This Row],[Stage dry mass]] -> 965489.38 | J12: =9.81*LeInitialSizingTable[[#This Row],[Specific impulse]]*LN(LeInitialSizingTable[[#This Row],[Wet mass]]/(LeInitialSizingTable[[#This Row],[Stage dry mass]]+LeInitialSizingTable[[#This Row],[Final mass]])) -> 4776.7327 | K12: 60 | L12: =9.81*LeInitialSizingTable[[#This Row],[Specific impulse]]*(LeInitialSizingTable[[#This Row],[Propellant mass]]/LeInitialSizingTable[[#This Row],[Burn time]]) -> 34475134 | M12: =LeInitialSizingTable[[#This Row],[Thrust]]*LeInitialSizingTable[[#This Row],[Burn time]] -> 2.068508e+09 | N12: =SUM($J$11:J12) -> 9553.4655
A13: 3 | B13: =I12 -> 965489.38 | C13: YES | D13: Liquid | E13: Methalox (LOX/CH4) | F13: =IF(LeInitialSizingTable[[#This Row],[Fuel type?]] = "Solid", INDEX(IF(LeInitialSizingTable[[#This Row],[In vacuum?]] = "YES", TheDropdownMenuTable_InitialSizing[Isp (solid, vacuum)], TheDropdownMenuTable_InitialSizing[Isp (solid, SL)]), MATCH(LeInitialSizingTable[[#This Row],[Fuel]], TheDropdownMenuTable_InitialSizing[Fuel (solid)], 0)), IF(LeInitialSizingTable[[#This Row],[Fuel type?]] = "Liquid", INDEX(IF(LeInitialSizingTable[[#This Row],[In vacuum?]] = "YES", TheDropdownMenuTable_InitialSizing[Isp (liquid, vacuum)], TheDropdownMenuTable_InitialSizing[Isp (liquid, SL)]), MATCH(LeInitialSizingTable[[#This Row],[Fuel]], TheDropdownMenuTable_InitialSizing[Fuel (liquid)], 0)), INDEX(IF(LeInitialSizingTable[[#This Row],[In vacuum?]] = "YES", TheDropdownMenuTable_InitialSizing[Isp (IDFK, vacuum)], TheDropdownMenuTable_InitialSizing[Isp (IDFK, SL)]), MATCH(LeInitialSizingTable[[#This Row],[Fuel]], TheDropdownMenuTable_InitialSizing[Fuel (IDFK)], 0)))) -> 368.50158 | G13: =$C$6*LeInitialSizingTable[[#This Row],[Final mass]] -> 96548.938 | H13: =($C$5*(LeInitialSizingTable[[#This Row],[Stage dry mass]]+LeInitialSizingTable[[#This Row],[Final mass]]))/(1-$C$5) -> 9558344.9 | I13: =LeInitialSizingTable[[#This Row],[Propellant mass]] + LeInitialSizingTable[[#This Row],[Stage dry mass]] -> 9654893.8 | J13: =9.81*LeInitialSizingTable[[#This Row],[Specific impulse]]*LN(LeInitialSizingTable[[#This Row],[Wet mass]]/(LeInitialSizingTable[[#This Row],[Stage dry mass]]+LeInitialSizingTable[[#This Row],[Final mass]])) -> 7979.2999 | K13: 120 | L13: =9.81*LeInitialSizingTable[[#This Row],[Specific impulse]]*(LeInitialSizingTable[[#This Row],[Propellant mass]]/LeInitialSizingTable[[#This Row],[Burn time]]) -> 2.8794518e+08 | M13: =LeInitialSizingTable[[#This Row],[Thrust]]*LeInitialSizingTable[[#This Row],[Burn time]] -> 3.4553422e+10 | N13: =SUM($J$11:J13) -> 17532.765
A14: 4 | B14: =I13 -> 9654893.8 | F14: =IF(LeInitialSizingTable[[#This Row],[Fuel type?]] = "Solid", INDEX(IF(LeInitialSizingTable[[#This Row],[In vacuum?]] = "YES", TheDropdownMenuTable_InitialSizing[Isp (solid, vacuum)], TheDropdownMenuTable_InitialSizing[Isp (solid, SL)]), MATCH(LeInitialSizingTable[[#This Row],[Fuel]], TheDropdownMenuTable_InitialSizing[Fuel (solid)], 0)), IF(LeInitialSizingTable[[#This Row],[Fuel type?]] = "Liquid", INDEX(IF(LeInitialSizingTable[[#This Row],[In vacuum?]] = "YES", TheDropdownMenuTable_InitialSizing[Isp (liquid, vacuum)], TheDropdownMenuTable_InitialSizing[Isp (liquid, SL)]), MATCH(LeInitialSizingTable[[#This Row],[Fuel]], TheDropdownMenuTable_InitialSizing[Fuel (liquid)], 0)), INDEX(IF(LeInitialSizingTable[[#This Row],[In vacuum?]] = "YES", TheDropdownMenuTable_InitialSizing[Isp (IDFK, vacuum)], TheDropdownMenuTable_InitialSizing[Isp (IDFK, SL)]), MATCH(LeInitialSizingTable[[#This Row],[Fuel]], TheDropdownMenuTable_InitialSizing[Fuel (IDFK)], 0)))) -> #N/A | G14: =$C$6*LeInitialSizingTable[[#This Row],[Final mass]] -> 965489.38 | H14: =($C$5*(LeInitialSizingTable[[#This Row],[Stage dry mass]]+LeInitialSizingTable[[#This Row],[Final mass]]))/(1-$C$5) -> 95583449 | I14: =LeInitialSizingTable[[#This Row],[Propellant mass]] + LeInitialSizingTable[[#This Row],[Stage dry mass]] -> 96548938 | J14: =9.81*LeInitialSizingTable[[#This Row],[Specific impulse]]*LN(LeInitialSizingTable[[#This Row],[Wet mass]]/(LeInitialSizingTable[[#This Row],[Stage dry mass]]+LeInitialSizingTable[[#This Row],[Final mass]])) -> #N/A | L14: =9.81*LeInitialSizingTable[[#This Row],[Specific impulse]]*(LeInitialSizingTable[[#This Row],[Propellant mass]]/LeInitialSizingTable[[#This Row],[Burn time]]) -> #N/A | M14: =LeInitialSizingTable[[#This Row],[Thrust]]*LeInitialSizingTable[[#This Row],[Burn time]] -> #N/A | N14: =SUM($J$11:J14) -> #N/A
A15: 5 | B15: =I14 -> 96548938 | F15: =IF(LeInitialSizingTable[[#This Row],[Fuel type?]] = "Solid", INDEX(IF(LeInitialSizingTable[[#This Row],[In vacuum?]] = "YES", TheDropdownMenuTable_InitialSizing[Isp (solid, vacuum)], TheDropdownMenuTable_InitialSizing[Isp (solid, SL)]), MATCH(LeInitialSizingTable[[#This Row],[Fuel]], TheDropdownMenuTable_InitialSizing[Fuel (solid)], 0)), IF(LeInitialSizingTable[[#This Row],[Fuel type?]] = "Liquid", INDEX(IF(LeInitialSizingTable[[#This Row],[In vacuum?]] = "YES", TheDropdownMenuTable_InitialSizing[Isp (liquid, vacuum)], TheDropdownMenuTable_InitialSizing[Isp (liquid, SL)]), MATCH(LeInitialSizingTable[[#This Row],[Fuel]], TheDropdownMenuTable_InitialSizing[Fuel (liquid)], 0)), INDEX(IF(LeInitialSizingTable[[#This Row],[In vacuum?]] = "YES", TheDropdownMenuTable_InitialSizing[Isp (IDFK, vacuum)], TheDropdownMenuTable_InitialSizing[Isp (IDFK, SL)]), MATCH(LeInitialSizingTable[[#This Row],[Fuel]], TheDropdownMenuTable_InitialSizing[Fuel (IDFK)], 0)))) -> #N/A | G15: =$C$6*LeInitialSizingTable[[#This Row],[Final mass]] -> 9654893.8 | H15: =($C$5*(LeInitialSizingTable[[#This Row],[Stage dry mass]]+LeInitialSizingTable[[#This Row],[Final mass]]))/(1-$C$5) -> 9.5583449e+08 | I15: =LeInitialSizingTable[[#This Row],[Propellant mass]] + LeInitialSizingTable[[#This Row],[Stage dry mass]] -> 9.6548938e+08 | J15: =9.81*LeInitialSizingTable[[#This Row],[Specific impulse]]*LN(LeInitialSizingTable[[#This Row],[Wet mass]]/(LeInitialSizingTable[[#This Row],[Stage dry mass]]+LeInitialSizingTable[[#This Row],[Final mass]])) -> #N/A | L15: =9.81*LeInitialSizingTable[[#This Row],[Specific impulse]]*(LeInitialSizingTable[[#This Row],[Propellant mass]]/LeInitialSizingTable[[#This Row],[Burn time]]) -> #N/A | M15: =LeInitialSizingTable[[#This Row],[Thrust]]*LeInitialSizingTable[[#This Row],[Burn time]] -> #N/A | N15: =SUM($J$11:J15) -> #N/A
A16: 6 | B16: =I15 -> 9.6548938e+08 | F16: =IF(LeInitialSizingTable[[#This Row],[Fuel type?]] = "Solid", INDEX(IF(LeInitialSizingTable[[#This Row],[In vacuum?]] = "YES", TheDropdownMenuTable_InitialSizing[Isp (solid, vacuum)], TheDropdownMenuTable_InitialSizing[Isp (solid, SL)]), MATCH(LeInitialSizingTable[[#This Row],[Fuel]], TheDropdownMenuTable_InitialSizing[Fuel (solid)], 0)), IF(LeInitialSizingTable[[#This Row],[Fuel type?]] = "Liquid", INDEX(IF(LeInitialSizingTable[[#This Row],[In vacuum?]] = "YES", TheDropdownMenuTable_InitialSizing[Isp (liquid, vacuum)], TheDropdownMenuTable_InitialSizing[Isp (liquid, SL)]), MATCH(LeInitialSizingTable[[#This Row],[Fuel]], TheDropdownMenuTable_InitialSizing[Fuel (liquid)], 0)), INDEX(IF(LeInitialSizingTable[[#This Row],[In vacuum?]] = "YES", TheDropdownMenuTable_InitialSizing[Isp (IDFK, vacuum)], TheDropdownMenuTable_InitialSizing[Isp (IDFK, SL)]), MATCH(LeInitialSizingTable[[#This Row],[Fuel]], TheDropdownMenuTable_InitialSizing[Fuel (IDFK)], 0)))) -> #N/A | G16: =$C$6*LeInitialSizingTable[[#This Row],[Final mass]] -> 96548938 | H16: =($C$5*(LeInitialSizingTable[[#This Row],[Stage dry mass]]+LeInitialSizingTable[[#This Row],[Final mass]]))/(1-$C$5) -> 9.5583449e+09 | I16: =LeInitialSizingTable[[#This Row],[Propellant mass]] + LeInitialSizingTable[[#This Row],[Stage dry mass]] -> 9.6548938e+09 | J16: =9.81*LeInitialSizingTable[[#This Row],[Specific impulse]]*LN(LeInitialSizingTable[[#This Row],[Wet mass]]/(LeInitialSizingTable[[#This Row],[Stage dry mass]]+LeInitialSizingTable[[#This Row],[Final mass]])) -> #N/A | L16: =9.81*LeInitialSizingTable[[#This Row],[Specific impulse]]*(LeInitialSizingTable[[#This Row],[Propellant mass]]/LeInitialSizingTable[[#This Row],[Burn time]]) -> #N/A | M16: =LeInitialSizingTable[[#This Row],[Thrust]]*LeInitialSizingTable[[#This Row],[Burn time]] -> #N/A | N16: =SUM($J$11:J16) -> #N/A
A17: 7 | B17: =I16 -> 9.6548938e+09 | F17: =IF(LeInitialSizingTable[[#This Row],[Fuel type?]] = "Solid", INDEX(IF(LeInitialSizingTable[[#This Row],[In vacuum?]] = "YES", TheDropdownMenuTable_InitialSizing[Isp (solid, vacuum)], TheDropdownMenuTable_InitialSizing[Isp (solid, SL)]), MATCH(LeInitialSizingTable[[#This Row],[Fuel]], TheDropdownMenuTable_InitialSizing[Fuel (solid)], 0)), IF(LeInitialSizingTable[[#This Row],[Fuel type?]] = "Liquid", INDEX(IF(LeInitialSizingTable[[#This Row],[In vacuum?]] = "YES", TheDropdownMenuTable_InitialSizing[Isp (liquid, vacuum)], TheDropdownMenuTable_InitialSizing[Isp (liquid, SL)]), MATCH(LeInitialSizingTable[[#This Row],[Fuel]], TheDropdownMenuTable_InitialSizing[Fuel (liquid)], 0)), INDEX(IF(LeInitialSizingTable[[#This Row],[In vacuum?]] = "YES", TheDropdownMenuTable_InitialSizing[Isp (IDFK, vacuum)], TheDropdownMenuTable_InitialSizing[Isp (IDFK, SL)]), MATCH(LeInitialSizingTable[[#This Row],[Fuel]], TheDropdownMenuTable_InitialSizing[Fuel (IDFK)], 0)))) -> #N/A | G17: =$C$6*LeInitialSizingTable[[#This Row],[Final mass]] -> 9.6548938e+08 | H17: =($C$5*(LeInitialSizingTable[[#This Row],[Stage dry mass]]+LeInitialSizingTable[[#This Row],[Final mass]]))/(1-$C$5) -> 9.5583449e+10 | I17: =LeInitialSizingTable[[#This Row],[Propellant mass]] + LeInitialSizingTable[[#This Row],[Stage dry mass]] -> 9.6548938e+10 | J17: =9.81*LeInitialSizingTable[[#This Row],[Specific impulse]]*LN(LeInitialSizingTable[[#This Row],[Wet mass]]/(LeInitialSizingTable[[#This Row],[Stage dry mass]]+LeInitialSizingTable[[#This Row],[Final mass]])) -> #N/A | L17: =9.81*LeInitialSizingTable[[#This Row],[Specific impulse]]*(LeInitialSizingTable[[#This Row],[Propellant mass]]/LeInitialSizingTable[[#This Row],[Burn time]]) -> #N/A | M17: =LeInitialSizingTable[[#This Row],[Thrust]]*LeInitialSizingTable[[#This Row],[Burn time]] -> #N/A | N17: =SUM($J$11:J17) -> #N/A
A18: 8 | B18: =I17 -> 9.6548938e+10 | F18: =IF(LeInitialSizingTable[[#This Row],[Fuel type?]] = "Solid", INDEX(IF(LeInitialSizingTable[[#This Row],[In vacuum?]] = "YES", TheDropdownMenuTable_InitialSizing[Isp (solid, vacuum)], TheDropdownMenuTable_InitialSizing[Isp (solid, SL)]), MATCH(LeInitialSizingTable[[#This Row],[Fuel]], TheDropdownMenuTable_InitialSizing[Fuel (solid)], 0)), IF(LeInitialSizingTable[[#This Row],[Fuel type?]] = "Liquid", INDEX(IF(LeInitialSizingTable[[#This Row],[In vacuum?]] = "YES", TheDropdownMenuTable_InitialSizing[Isp (liquid, vacuum)], TheDropdownMenuTable_InitialSizing[Isp (liquid, SL)]), MATCH(LeInitialSizingTable[[#This Row],[Fuel]], TheDropdownMenuTable_InitialSizing[Fuel (liquid)], 0)), INDEX(IF(LeInitialSizingTable[[#This Row],[In vacuum?]] = "YES", TheDropdownMenuTable_InitialSizing[Isp (IDFK, vacuum)], TheDropdownMenuTable_InitialSizing[Isp (IDFK, SL)]), MATCH(LeInitialSizingTable[[#This Row],[Fuel]], TheDropdownMenuTable_InitialSizing[Fuel (IDFK)], 0)))) -> #N/A | G18: =$C$6*LeInitialSizingTable[[#This Row],[Final mass]] -> 9.6548938e+09 | H18: =($C$5*(LeInitialSizingTable[[#This Row],[Stage dry mass]]+LeInitialSizingTable[[#This Row],[Final mass]]))/(1-$C$5) -> 9.5583449e+11 | I18: =LeInitialSizingTable[[#This Row],[Propellant mass]] + LeInitialSizingTable[[#This Row],[Stage dry mass]] -> 9.6548938e+11 | J18: =9.81*LeInitialSizingTable[[#This Row],[Specific impulse]]*LN(LeInitialSizingTable[[#This Row],[Wet mass]]/(LeInitialSizingTable[[#This Row],[Stage dry mass]]+LeInitialSizingTable[[#This Row],[Final mass]])) -> #N/A | L18: =9.81*LeInitialSizingTable[[#This Row],[Specific impulse]]*(LeInitialSizingTable[[#This Row],[Propellant mass]]/LeInitialSizingTable[[#This Row],[Burn time]]) -> #N/A | M18: =LeInitialSizingTable[[#This Row],[Thrust]]*LeInitialSizingTable[[#This Row],[Burn time]] -> #N/A | N18: =SUM($J$11:J18) -> #N/A
A19: 9 | B19: =I18 -> 9.6548938e+11 | F19: =IF(LeInitialSizingTable[[#This Row],[Fuel type?]] = "Solid", INDEX(IF(LeInitialSizingTable[[#This Row],[In vacuum?]] = "YES", TheDropdownMenuTable_InitialSizing[Isp (solid, vacuum)], TheDropdownMenuTable_InitialSizing[Isp (solid, SL)]), MATCH(LeInitialSizingTable[[#This Row],[Fuel]], TheDropdownMenuTable_InitialSizing[Fuel (solid)], 0)), IF(LeInitialSizingTable[[#This Row],[Fuel type?]] = "Liquid", INDEX(IF(LeInitialSizingTable[[#This Row],[In vacuum?]] = "YES", TheDropdownMenuTable_InitialSizing[Isp (liquid, vacuum)], TheDropdownMenuTable_InitialSizing[Isp (liquid, SL)]), MATCH(LeInitialSizingTable[[#This Row],[Fuel]], TheDropdownMenuTable_InitialSizing[Fuel (liquid)], 0)), INDEX(IF(LeInitialSizingTable[[#This Row],[In vacuum?]] = "YES", TheDropdownMenuTable_InitialSizing[Isp (IDFK, vacuum)], TheDropdownMenuTable_InitialSizing[Isp (IDFK, SL)]), MATCH(LeInitialSizingTable[[#This Row],[Fuel]], TheDropdownMenuTable_InitialSizing[Fuel (IDFK)], 0)))) -> #N/A | G19: =$C$6*LeInitialSizingTable[[#This Row],[Final mass]] -> 9.6548938e+10 | H19: =($C$5*(LeInitialSizingTable[[#This Row],[Stage dry mass]]+LeInitialSizingTable[[#This Row],[Final mass]]))/(1-$C$5) -> 9.5583449e+12 | I19: =LeInitialSizingTable[[#This Row],[Propellant mass]] + LeInitialSizingTable[[#This Row],[Stage dry mass]] -> 9.6548938e+12 | J19: =9.81*LeInitialSizingTable[[#This Row],[Specific impulse]]*LN(LeInitialSizingTable[[#This Row],[Wet mass]]/(LeInitialSizingTable[[#This Row],[Stage dry mass]]+LeInitialSizingTable[[#This Row],[Final mass]])) -> #N/A | L19: =9.81*LeInitialSizingTable[[#This Row],[Specific impulse]]*(LeInitialSizingTable[[#This Row],[Propellant mass]]/LeInitialSizingTable[[#This Row],[Burn time]]) -> #N/A | M19: =LeInitialSizingTable[[#This Row],[Thrust]]*LeInitialSizingTable[[#This Row],[Burn time]] -> #N/A | N19: =SUM($J$11:J19) -> #N/A
A20: 10 | B20: =I19 -> 9.6548938e+12 | F20: =IF(LeInitialSizingTable[[#This Row],[Fuel type?]] = "Solid", INDEX(IF(LeInitialSizingTable[[#This Row],[In vacuum?]] = "YES", TheDropdownMenuTable_InitialSizing[Isp (solid, vacuum)], TheDropdownMenuTable_InitialSizing[Isp (solid, SL)]), MATCH(LeInitialSizingTable[[#This Row],[Fuel]], TheDropdownMenuTable_InitialSizing[Fuel (solid)], 0)), IF(LeInitialSizingTable[[#This Row],[Fuel type?]] = "Liquid", INDEX(IF(LeInitialSizingTable[[#This Row],[In vacuum?]] = "YES", TheDropdownMenuTable_InitialSizing[Isp (liquid, vacuum)], TheDropdownMenuTable_InitialSizing[Isp (liquid, SL)]), MATCH(LeInitialSizingTable[[#This Row],[Fuel]], TheDropdownMenuTable_InitialSizing[Fuel (liquid)], 0)), INDEX(IF(LeInitialSizingTable[[#This Row],[In vacuum?]] = "YES", TheDropdownMenuTable_InitialSizing[Isp (IDFK, vacuum)], TheDropdownMenuTable_InitialSizing[Isp (IDFK, SL)]), MATCH(LeInitialSizingTable[[#This Row],[Fuel]], TheDropdownMenuTable_InitialSizing[Fuel (IDFK)], 0)))) -> #N/A | G20: =$C$6*LeInitialSizingTable[[#This Row],[Final mass]] -> 9.6548938e+11 | H20: =($C$5*(LeInitialSizingTable[[#This Row],[Stage dry mass]]+LeInitialSizingTable[[#This Row],[Final mass]]))/(1-$C$5) -> 9.5583449e+13 | I20: =LeInitialSizingTable[[#This Row],[Propellant mass]] + LeInitialSizingTable[[#This Row],[Stage dry mass]] -> 9.6548938e+13 | J20: =9.81*LeInitialSizingTable[[#This Row],[Specific impulse]]*LN(LeInitialSizingTable[[#This Row],[Wet mass]]/(LeInitialSizingTable[[#This Row],[Stage dry mass]]+LeInitialSizingTable[[#This Row],[Final mass]])) -> #N/A | L20: =9.81*LeInitialSizingTable[[#This Row],[Specific impulse]]*(LeInitialSizingTable[[#This Row],[Propellant mass]]/LeInitialSizingTable[[#This Row],[Burn time]]) -> #N/A | M20: =LeInitialSizingTable[[#This Row],[Thrust]]*LeInitialSizingTable[[#This Row],[Burn time]] -> #N/A | N20: =SUM($J$11:J20) -> #N/A
G23: DO NOT EVER TOUCH THIS CELL!!! -> | I23: {=_xlfn._xlws.PY(8,1,LeInitialSizingTable[#All])} -> #VALUE!
F24: PRELIMINARY ROCKET STATS
F25: Stages | G25: {=_xlfn._xlws.PY(9,0,'Data Input'!$C$7)} -> 3 | H25: -
F26: Calculated delta-v budget | G26: {=_xlfn._xlws.PY(10,0,$G$25)} -> 17532.765 | H26: m*s^-1
F27: Empty weight | G27: {=_xlfn._xlws.PY(11,0,$G$25)} -> 107169.32 | H27: kg
F28: Liftoff weight | G28: {=_xlfn._xlws.PY(12,0,$G$25)} -> 10716932 | H28: kg
F29: Fulfils average delta-v? | G29: {=_xlfn._xlws.PY(13,0,$G$26,'Data Input'!$F$32)} -> Yes! OwO | H29: (Boolean)
F30: Fulfils max delta-v? | G30: {=_xlfn._xlws.PY(13,0,$G$26,'Data Input'!$F$33)} -> No... T_T | H30: (Boolean)
F31: Optimise rocket? | G31: YES | H31: (Boolean)
F32: Optimised delta-v budget | G32: {=_xlfn._xlws.PY(14,0,$G$26,$G$31,$C$5,$C$6,'Data Input'!$F$32,'Data Input'!$F$33,'Data Input'!$C$7,'Data Input'!$C$7)} -> 25280.941 | H32: m*s^-1
F33: Fulfils average delta-v? | G33: {=_xlfn._xlws.PY(13,0,$G$32,'Data Input'!$F$32)} -> Yes! OwO | H33: (Boolean)
F34: Fulfils max delta-v? | G34: {=_xlfn._xlws.PY(13,0,$G$32,'Data Input'!$F$33)} -> Yes! OwO | H34: (Boolean)
A36: HOW TO OTHER TABLE
A38: DO NOT TOUCH THE FIRST TWO COLUMNS!!! Insert fuel type in the fuel columns and subsequently its specific impulse in the respective columns. When one isn't available, approximate SLIsp = 0.667*VacIsp or inversely VacIsp = 1.5*SLIsp
A40: Vacuum? | B40: Fuel type? | C40: Fuel (solid) | D40: Isp (solid, vacuum) | E40: Isp (solid, SL) | F40: Fuel (liquid) | G40: Isp (liquid, vacuum) | H40: Isp (liquid, SL) | I40: Fuel (IDFK) | J40: Isp (IDFK, vacuum) | K40: Isp (IDFK, SL)
A41: YES | B41: Solid | C41: HTPB (LAPAN) | D41: =1.5*TheDropdownMenuTable_InitialSizing[[#This Row],[Isp (solid, SL)]] -> 330.9 | E41: =AVERAGE(220, 220, 220, 203, 240) -> 220.6 | F41: Hydrolox (LOX/LH2) | G41: 454.842 | H41: 388.78695 | I41: ALICE (Ice + Al) | J41: =1.5*TheDropdownMenuTable_InitialSizing[[#This Row],[Isp (IDFK, SL)]] -> 315 | K41: 210
A42: NO | B42: Liquid | C42: Rocket candy | D42: =1.5*TheDropdownMenuTable_InitialSizing[[#This Row],[Isp (solid, SL)]] -> 244.122 | E42: 162.748 | F42: Methalox (LOX/CH4) | G42: 368.50158 | H42: 309.27625 | I42: HTPB/Paraffin | J42: =1.5*TheDropdownMenuTable_InitialSizing[[#This Row],[Isp (IDFK, SL)]] -> 337.5 | K42: 225
B43: Some weird third thing | C43: APCP×HTPB ([UwU], [1]) | D43: =1.5*TheDropdownMenuTable_InitialSizing[[#This Row],[Isp (solid, SL)]] -> 393 | E43: 262 | F43: Kerolox (LOX/RP-1) | G43: 357.79817 | H43: 299.79613 | I43: LOX/HTPB | J43: =1.5*TheDropdownMenuTable_InitialSizing[[#This Row],[Isp (IDFK, SL)]] -> 576 | K43: 384
C44: APCP×PBAN ([UwU], [1]) | D44: =1.5*TheDropdownMenuTable_InitialSizing[[#This Row],[Isp (solid, SL)]] -> 399 | E44: 266 | F44: N2O4/UDMH×N2H4 (Aerozine 50) | G44: 341.38634 | H44: 288.58308 | I44: MMH only (NASA OMS) | J44: 316 | K44: =(2*TheDropdownMenuTable_InitialSizing[[#This Row],[Isp (IDFK, vacuum)]])/3 -> 210.66667
C45: Black powder | D45: =1.5*TheDropdownMenuTable_InitialSizing[[#This Row],[Isp (solid, SL)]] -> 116.25 | E45: 77.5 | F45: N2O4/UDMH | G45: 333 | H45: 285
F46: N2O4/N2H4 | G46: 343.42508 | H46: 291.74312
F47: N2O4/MMH | G47: 341.18247 | H47: 288.17533
B52: DON'T TOUCH THIS TABLE AAAAAAAAAAAAAAAAAAA--
B53: Fuel type | C53: Proportion, fuel | D53: Proportion, oxidiser
...

Sheet Geometry
B2: HOW TO TABLE
B4: Insert numbers in yellow-tinted cells. The initial geometry will be shown in the chart aside the inputs.
B6: STAGES
B7: Number | C7: ='Data Input'!$C$7 -> 3
B9: DIMENSIONS | F9: PROPORTION
B10: Data | C10: Sub-data | D10: m | F10: Data | G10: %
B11: Total height | D11: =SUM($D$12:$D$22) -> 25 | F11: Interstage fairing
B12: Per-stage height | C12: Payload (fairing) | D12: 4 | F12: Computer stuff
C13: 1 | D13: 5 | F13: Fuel
C14: 2 | D14: 6 | F14: Engine
C15: 3 | D15: 10
C16: 4 | F16: DRAWING SIZE
C17: 5 | F17: Size | G17: A0
C18: 6 | F18: Width | G18: =_xlfn.IFNA(VLOOKUP($G$17, $B$71:$D$80, 2), "") -> 1189
C19: 7 | F19: Height | G19: =_xlfn.IFNA(VLOOKUP($G$17, $B$71:$D$80, 3), "") -> 841
C20: 8 | F20: Scale to reality
C21: 9 | F21: Drawing style | G21: American (third-angle)
C22: 10
B23: Stage diameter | C23: 1
C24: 2
C25: 3
C26: 4
C27: 5
C28: 6
C29: 7
C30: 8
C31: 9
C32: 10
B33: Fuel type | C33: 1 | D33: =IF(VLOOKUP($C33, 'Initial Sizing'!$A$11:$N$20, 4, TRUE) = 0, "", VLOOKUP($C33, 'Initial Sizing'!$A$11:$N$20, 4, TRUE)) -> Solid
C34: 2 | D34: =IF(VLOOKUP($C34, 'Initial Sizing'!$A$11:$N$20, 4, TRUE) = 0, "", VLOOKUP($C34, 'Initial Sizing'!$A$11:$N$20, 4, TRUE)) -> Solid
C35: 3 | D35: =IF(VLOOKUP($C35, 'Initial Sizing'!$A$11:$N$20, 4, TRUE) = 0, "", VLOOKUP($C35, 'Initial Sizing'!$A$11:$N$20, 4, TRUE)) -> Liquid
C36: 4 | D36: =IF(VLOOKUP($C36, 'Initial Sizing'!$A$11:$N$20, 4, TRUE) = 0, "", VLOOKUP($C36, 'Initial Sizing'!$A$11:$N$20, 4, TRUE))
C37: 5 | D37: =IF(VLOOKUP($C37, 'Initial Sizing'!$A$11:$N$20, 4, TRUE) = 0, "", VLOOKUP($C37, 'Initial Sizing'!$A$11:$N$20, 4, TRUE))
C38: 6 | D38: =IF(VLOOKUP($C38, 'Initial Sizing'!$A$11:$N$20, 4, TRUE) = 0, "", VLOOKUP($C38, 'Initial Sizing'!$A$11:$N$20, 4, TRUE))
C39: 7 | D39: =IF(VLOOKUP($C39, 'Initial Sizing'!$A$11:$N$20, 4, TRUE) = 0, "", VLOOKUP($C39, 'Initial Sizing'!$A$11:$N$20, 4, TRUE))
C40: 8 | D40: =IF(VLOOKUP($C40, 'Initial Sizing'!$A$11:$N$20, 4, TRUE) = 0, "", VLOOKUP($C40, 'Initial Sizing'!$A$11:$N$20, 4, TRUE))
C41: 9 | D41: =IF(VLOOKUP($C41, 'Initial Sizing'!$A$11:$N$20, 4, TRUE) = 0, "", VLOOKUP($C41, 'Initial Sizing'!$A$11:$N$20, 4, TRUE))
C42: 10 | D42: =IF(VLOOKUP($C42, 'Initial Sizing'!$A$11:$N$20, 4, TRUE) = 0, "", VLOOKUP($C42, 'Initial Sizing'!$A$11:$N$20, 4, TRUE))
B43: Engine number | C43: 1 | D43: 1
C44: 2 | D44: 2
...

Sheet Weight Analysis - Initial
A1: HOW TO TABLE
A3: Insert numbers in yellow-tinted cells, optionally in orange-tinted one.
A5: Things inputted | B5: Input value | D5: Stage | E5: General subdvision | F5: Specific subdivision | G5: Value | H5: Unit | I5: Value | J5: Unit
A6: Propellant mass fraction | B6: ='Initial Sizing'!$C$5 -> 0.9 | D6: 1 | E6: Propellant | F6: Fuel
A7: Dry mass ratio | B7: ='Initial Sizing'!$C$6 -> 0.1 | F7: Oxidiser
A8: Empty weight, initial sizing (kg) | B8: ='Initial Sizing'!$G$27 -> 107169.32 | E8: Structure | F8: Tanks
A9: GLOW, initial sizing (kg) | B9: ='Initial Sizing'!$G$28 -> 10716932 | F9: "Skeleton"
A10: Max. possble delta-V, initial sizing (m*s^-1) | B10: =MAX('Initial Sizing'!$G$26, 'Initial Sizing'!$G$32) -> 25280.941
A12: Stage | B12: Desired thrust-to-weight ratio
A13: 1
A14: 2
A15: 3
A16: 4
A17: 5
A18: 6
A19: 7
A20: 8
A21: 9
A22: 10

Sheet Log
B2: HOW TO TABLES
A3: Ctrl+; and then Ctrl+Shift+; on the date and time cell before inserting your local time zone. Pick your abbreviation (that can be set on the orange table). State in a numbered list concisely what you've done. Copy your Github commits here if you came from there
A5: Date and Time | B5: Who?* | C5: Revision | D5: Addition
A6: 11/01/2025, 23:00 UTC+7 | B6: [MNA] | C6: - | D6: 1. Initial sizing 2. Introduction Page | F6: * = (Co-)Authors Abbreviation Index Enter current work position or schooling institution, using official English name. Company names must be the legal one, not just the brand If you can't disclose where you work (Academic institution MUST be disclosed), fill with [LE SECRET ONHONHON~]
A7: 12/01/2025, 05:07 UTC+7 | B7: [MNA] | C7: - | D7: 1. Log | F7: Abbr. | G7: Name | H7: Work/School
A8: 12/01/2025,15:01 UTC+7 | B8: [MNA] | C8: 1. Added to-do list in Intro page 2. Revised wording in Intro page | D8: - | F8: [BGD] | G8: Bagaskara Adhiguna, S.T. | H8: Graduate Computer Engineering Study Program, Faculty of Engineering Bina Nusantara University
A9: 13/01/2025, 05:18 UTC+7 | B9: [MNA] | C9: 1. Added expected features | D9: - | F9: [BJB] | G9: Benedict Julian Zefanya Batubara | H9: Undergraduate Student Aerospace Engineering Study Program, Faculty of Mechanic and Aerospace Engineering Institut Teknologi Bandung
A10: 13/01/2025, 11:40 UTC+7 | B10: [MNA] | C10: - | D10: 1. Uploaded file to Github for further collaboration | F10: [DAS] | G10: David Soegijanto, S.T. | H10: Graduate Student Aerospace Engineering Study Program, Faculty of Mechanic and Aerospace Engineering Institut Teknologi Bandung
A11: 13/01/2025, 11:41 UTC+7 | B11: [MNA] | C11: 1. Revised Github readme, therefore intro spreadsheet | D11: - | F11: [JHS] | G11: Jethro Hotasi Sinaga, S.T. | H11: Graduate Aerospace Engineering Study Program, Faculty of Mechanic and Aerospace Engineering Institut Teknologi Bandung
A12: 13/01/2025, 11:51 UTC+7 | B12: [MNA] | C12: 1. Some formatting changes to intro spreadsheet and or Github readme | D12: - | F12: [MNA] | G12: Muhammad Naufal Afif, S.T. | H12: Graduate Aerospace Engineering Study Program, Faculty of Mechanic and Aerospace Engineering Institut Teknologi Bandung
A13: 13/01/2025, 19:21 UTC+7 | B13: [MNA] | C13: 1. Initial sizing sheet now interconnected with data input data 2. Additional details on how to input logs 3. Some more statistics on initial sizing | D13: 1. Data input | F13: [REP] | G13: Dr. Eng. Ridanto Eko Poetro, S.T, M.Sc. | H13: Lecturer Aerospace Engineering Study Program, Faculty of Mechanic and Aerospace Engineering Institut Teknologi Bandung
A14: 14/01/2025, 14:13 UTC+7 | B14: [MNA] | C14: 1. Delta-v calculation in input sheet 2. Started work on the orbital calculation for input (single-stage to desired orbit) | D14: - | F14: [TIO] | G14: Ir. Toto Indriyanto, M.Sc., Ph.D. | H14: Lecturer Aerospace Engineering Study Program, Faculty of Mechanic and Aerospace Engineering Institut Teknologi Bandung
A15: 14/01/2025, 21:18 UTC+7 | B15: [MNA] | C15: 1. Finally made data input work 2. Proper initial sizing, about damn time | D15: -
A16: 15/01/2025, 10:59 UTC+7 | B16: [MNA] | C16: 1. Improved data input | D16: -
A17: 16/01/2025, 08:51 UTC+7 | B17: [MNA] | C17: 1. Improved initial sizing, now with Python! 2. Put initial sizing data as pandas dataframe | D17: -
A18: 16/01/2025, 13:08 UTC+7 | B18: [MNA] | C18: 1. Improved needed delta-v budget calculations | D18: -
A19: 16/01/2025, 16:18 UTC+7 | B19: [MNA] | C19: 1. Uploaded revision to GitHub a.Officially added co-authors b. Refined initial sizing algorithm | D19: -
A20: 17/01/2025, 16:50 UTC+7 | B20: [MNA] | C20: 1. Improved expected rocket statistics in data input: Now With Python! 2. Improved log tracking 3. Improved initial sizing | D20: -
A21: 22/01/2025, 16:30 UTC+7 | B21: [MNA] | C21: 1. Revised Python code for data sizing 2. Switched Python-enabled cell from being Python objects to become Excel values | D21: 1. "Goal seek" optimisation for rocket initial sizing
A22: 20/08/2025, 14:20 UTC+7 | B22: [MNA] | C22: 1. Revised lead contributor's position | D22: -
A23: 21/08/2025, 21:46 UTC+7 | B23: [MNA] | C23: 1. Added new contributor 2. Update README.md in GitHub 3. Updated SomRMWT in GitHub | D23: -
A24: 27/08/2025, 00:08 UTC+7 | B24: [MNA] | C24: 1. Added contributor and revised position 2. Cosmetic improvements | D24: 1. Fuel-oxidiser ratio table 2. Weight Analysis - Initial 3. Python coding as separate .py files for initial sizing and weight analysis
A25: 27/08/2025, 21:01 UTC+7 | B25: [MNA] | C25: 1. Information update on "Le Intro" | D25: -
A26: 22/09/2026, 15:04 UTC+7 | B26: [MNA] | C26: 1. Switched Gemoetry and Weight Analysis place in the workflow (Excel: L –> R) 2. Revised a contributor's title | D26: 1. Geometry, owo~!
A27: 23/09/2026, 22:53 UTC+7 | B27: [MNA] | C27: 1. Housekeeping 2. Sortation of features in "Le Intro" 3. Further progress on geometry 4. Revised a contributor's position | D27: -
G31: Last revision by: | H31: {=_xlfn.CONCAT(_xlfn.XLOOKUP(_xlfn.XLOOKUP(TRUE, LogTable[Who?*] <> "", LogTable[Who?*], "¯\_(ツ)_/¯", 0, -1), AuthorTable[Abbr.], AuthorTable[Name], "¯\_(ツ)_/¯", 0, 1), ", ", _xlfn.XLOOKUP(TRUE, LogTable[Date and Time] <> "", LogTable[Date and Time], "¯\_(ツ)_/¯", 0, -1))} -> Muhammad Naufal Afif, S.T., 23/09/2026, 22:53 UTC+7
